Workbook

Sheet 기본설정·안내
A1: 기간제교원 발령대장 입력·출력 기본파일
A3: 기본 설정 | B3: 입력값
A4: 학교명(소속) | B4: 학돌중학교
A5: 발령권자 | B5: 학교장
A6: 기본 발령근거 | B6: 학돌중-
A7: 기재자날인
A8: 확인자날인
A9: 기본 비고
A11: 입력 원칙 | B11: 내용
A12: 입력 항목 | B12: 직위(급), 과목, 성명, 생년월일 또는 주민번호, 임용시작일, 임용종료일, 호봉을 입력합니다.
A13: 1행 1기간 | B13: 한 행에는 한 사람의 한 개 임용기간을 입력합니다.
A14: 발령일 | B14: 출력 시 임용시작일이 발령일로 자동 표시됩니다.
A15: 소속·발령권자 | B15: 위 기본 설정값이 발령대장 출력 시 자동 반영됩니다.
A16: 발령사항 | B16: 직위(급), 과목, 호봉, 임용기간으로 자동 작성됩니다.
A17: 주민번호 | B17: 경력증명서 발급을 위한 값이며 발령대장 출력에는 표시하지 않습니다.
A18: 인쇄 | B18: 발령대장_출력 시트의 1~4행을 인쇄 제목으로 반복 지정하면 편리합니다.

Sheet 발령대장_입력
A1: 직위(급) | B1: 과목 | C1: 성명 | D1: 생년월일 또는 주민번호 | E1: 임용시작일 | F1: 임용종료일 | G1: 호봉
A2: 기간제교사 | B2: 물리 | C2: 홍길동 | D2: 900101 | E2: 46082 | F2: 46446 | G2: 21
A3: 기간제교사
A4: 기간제교사
A5: 기간제교사
A6: 기간제교사
A7: 기간제교사
A8: 기간제교사
A9: 기간제교사
A10: 기간제교사
A11: 기간제교사
A12: 기간제교사
A13: 기간제교사
A14: 기간제교사
... A89: 기간제교사

Sheet 발령대장_출력
A1: ■ 교육공무원 인사기록 및 인사사무 처리 규칙 [별지 제24호서식] <개정 2013.11.13>
A2: 발 령 대 장
A4: 발 령 일 | B4: 소 속 | C4: 직위(직급) | D4: 성 명 | E4: 발 령 사 항 | F4: 발 령 권 자 | G4: 발 령 근 거 | H4: 기재자날인 | I4: 확인자날인 | J4: 비 고
A5: =IF(발령대장_입력!$C2="","",발령대장_입력!$E2) -> 46082 | B5: =IF($A5="","",IF(기본설정·안내!$B$4="","",기본설정·안내!$B$4)) -> 학돌중학교 | C5: =IF($A5="","",IF(발령대장_입력!$B2="",발령대장_입력!$A2,발령대장_입력!$A2&CHAR(10)&"("&발령대장_입력!$B2&")")) -> 기간제교사 (물리) | D5: =IF($A5="","",발령대장_입력!$C2) -> 홍길동 | E5: =IF($A5="","",발령대장_입력!$A2&"에 임함"&IF(발령대장_입력!$B2="","",CHAR(10)&"("&발령대장_입력!$B2&")")&IF(발령대장_입력!$G2="","",CHAR(10)&"("&SUBSTITUTE(SUBSTITUTE(발령대장_입력!$G2,"호봉","")," ","")&")호봉을 급함")&CHAR(10)&"임용기간: "&YEAR(발령대장_입력!$E2)&"."&MONTH(발령대장_입력!$E2)&"."&DAY(발령대장_입력!$E2)&"."&" ~ "&YEAR(발령대장_입력!$F2)&"."&MONTH(발령대장_입력!$F2)&"."&DAY(발령대장_입력!$F2)&".") -> 기간제교사에 임함 (물리) (21)호봉을 급함 임용기간: 2026.3.1. ~ 2027.2.28. | F5: =IF($A5="","",IF(기본설정·안내!$B$5="","",기본설정·안내!$B$5)) -> 학교장 | G5: =IF($A5="","",IF(기본설정·안내!$B$6="","",기본설정·안내!$B$6)) -> 학돌중- | H5: =IF($A5="","",IF(기본설정·안내!$B$7="","",기본설정·안내!$B$7)) | I5: =IF($A5="","",IF(기본설정·안내!$B$8="","",기본설정·안내!$B$8)) | J5: =IF($A5="","",IF(기본설정·안내!$B$9="","",기본설정·안내!$B$9))
A6: =IF(발령대장_입력!$C3="","",발령대장_입력!$E3) | B6: =IF($A6="","",IF(기본설정·안내!$B$4="","",기본설정·안내!$B$4)) | C6: =IF($A6="","",IF(발령대장_입력!$B3="",발령대장_입력!$A3,발령대장_입력!$A3&CHAR(10)&"("&발령대장_입력!$B3&")")) | D6: =IF($A6="","",발령대장_입력!$C3) | E6: =IF($A6="","",발령대장_입력!$A3&"에 임함"&IF(발령대장_입력!$B3="","",CHAR(10)&"("&발령대장_입력!$B3&")")&IF(발령대장_입력!$G3="","",CHAR(10)&"("&SUBSTITUTE(SUBSTITUTE(발령대장_입력!$G3,"호봉","")," ","")&")호봉을 급함")&CHAR(10)&"임용기간: "&YEAR(발령대장_입력!$E3)&"."&MONTH(발령대장_입력!$E3)&"."&DAY(발령대장_입력!$E3)&"."&" ~ "&YEAR(발령대장_입력!$F3)&"."&MONTH(발령대장_입력!$F3)&"."&DAY(발령대장_입력!$F3)&".") | F6: =IF($A6="","",IF(기본설정·안내!$B$5="","",기본설정·안내!$B$5)) | G6: =IF($A6="","",IF(기본설정·안내!$B$6="","",기본설정·안내!$B$6)) | H6: =IF($A6="","",IF(기본설정·안내!$B$7="","",기본설정·안내!$B$7)) | I6: =IF($A6="","",IF(기본설정·안내!$B$8="","",기본설정·안내!$B$8)) | J6: =IF($A6="","",IF(기본설정·안내!$B$9="","",기본설정·안내!$B$9))
A7: =IF(발령대장_입력!$C4="","",발령대장_입력!$E4) | B7: =IF($A7="","",IF(기본설정·안내!$B$4="","",기본설정·안내!$B$4)) | C7: =IF($A7="","",IF(발령대장_입력!$B4="",발령대장_입력!$A4,발령대장_입력!$A4&CHAR(10)&"("&발령대장_입력!$B4&")")) | D7: =IF($A7="","",발령대장_입력!$C4) | E7: =IF($A7="","",발령대장_입력!$A4&"에 임함"&IF(발령대장_입력!$B4="","",CHAR(10)&"("&발령대장_입력!$B4&")")&IF(발령대장_입력!$G4="","",CHAR(10)&"("&SUBSTITUTE(SUBSTITUTE(발령대장_입력!$G4,"호봉","")," ","")&")호봉을 급함")&CHAR(10)&"임용기간: "&YEAR(발령대장_입력!$E4)&"."&MONTH(발령대장_입력!$E4)&"."&DAY(발령대장_입력!$E4)&"."&" ~ "&YEAR(발령대장_입력!$F4)&"."&MONTH(발령대장_입력!$F4)&"."&DAY(발령대장_입력!$F4)&".") | F7: =IF($A7="","",IF(기본설정·안내!$B$5="","",기본설정·안내!$B$5)) | G7: =IF($A7="","",IF(기본설정·안내!$B$6="","",기본설정·안내!$B$6)) | H7: =IF($A7="","",IF(기본설정·안내!$B$7="","",기본설정·안내!$B$7)) | I7: =IF($A7="","",IF(기본설정·안내!$B$8="","",기본설정·안내!$B$8)) | J7: =IF($A7="","",IF(기본설정·안내!$B$9="","",기본설정·안내!$B$9))
A8: =IF(발령대장_입력!$C5="","",발령대장_입력!$E5) | B8: =IF($A8="","",IF(기본설정·안내!$B$4="","",기본설정·안내!$B$4)) | C8: =IF($A8="","",IF(발령대장_입력!$B5="",발령대장_입력!$A5,발령대장_입력!$A5&CHAR(10)&"("&발령대장_입력!$B5&")")) | D8: =IF($A8="","",발령대장_입력!$C5) | E8: =IF($A8="","",발령대장_입력!$A5&"에 임함"&IF(발령대장_입력!$B5="","",CHAR(10)&"("&발령대장_입력!$B5&")")&IF(발령대장_입력!$G5="","",CHAR(10)&"("&SUBSTITUTE(SUBSTITUTE(발령대장_입력!$G5,"호봉","")," ","")&")호봉을 급함")&CHAR(10)&"임용기간: "&YEAR(발령대장_입력!$E5)&"."&MONTH(발령대장_입력!$E5)&"."&DAY(발령대장_입력!$E5)&"."&" ~ "&YEAR(발령대장_입력!$F5)&"."&MONTH(발령대장_입력!$F5)&"."&DAY(발령대장_입력!$F5)&".") | F8: =IF($A8="","",IF(기본설정·안내!$B$5="","",기본설정·안내!$B$5)) | G8: =IF($A8="","",IF(기본설정·안내!$B$6="","",기본설정·안내!$B$6)) | H8: =IF($A8="","",IF(기본설정·안내!$B$7="","",기본설정·안내!$B$7)) | I8: =IF($A8="","",IF(기본설정·안내!$B$8="","",기본설정·안내!$B$8)) | J8: =IF($A8="","",IF(기본설정·안내!$B$9="","",기본설정·안내!$B$9))
A9: =IF(발령대장_입력!$C6="","",발령대장_입력!$E6) | B9: =IF($A9="","",IF(기본설정·안내!$B$4="","",기본설정·안내!$B$4)) | C9: =IF($A9="","",IF(발령대장_입력!$B6="",발령대장_입력!$A6,발령대장_입력!$A6&CHAR(10)&"("&발령대장_입력!$B6&")")) | D9: =IF($A9="","",발령대장_입력!$C6) | E9: =IF($A9="","",발령대장_입력!$A6&"에 임함"&IF(발령대장_입력!$B6="","",CHAR(10)&"("&발령대장_입력!$B6&")")&IF(발령대장_입력!$G6="","",CHAR(10)&"("&SUBSTITUTE(SUBSTITUTE(발령대장_입력!$G6,"호봉","")," ","")&")호봉을 급함")&CHAR(10)&"임용기간: "&YEAR(발령대장_입력!$E6)&"."&MONTH(발령대장_입력!$E6)&"."&DAY(발령대장_입력!$E6)&"."&" ~ "&YEAR(발령대장_입력!$F6)&"."&MONTH(발령대장_입력!$F6)&"."&DAY(발령대장_입력!$F6)&".") | F9: =IF($A9="","",IF(기본설정·안내!$B$5="","",기본설정·안내!$B$5)) | G9: =IF($A9="","",IF(기본설정·안내!$B$6="","",기본설정·안내!$B$6)) | H9: =IF($A9="","",IF(기본설정·안내!$B$7="","",기본설정·안내!$B$7)) | I9: =IF($A9="","",IF(기본설정·안내!$B$8="","",기본설정·안내!$B$8)) | J9: =IF($A9="","",IF(기본설정·안내!$B$9="","",기본설정·안내!$B$9))
A10: =IF(발령대장_입력!$C7="","",발령대장_입력!$E7) | B10: =IF($A10="","",IF(기본설정·안내!$B$4="","",기본설정·안내!$B$4)) | C10: =IF($A10="","",IF(발령대장_입력!$B7="",발령대장_입력!$A7,발령대장_입력!$A7&CHAR(10)&"("&발령대장_입력!$B7&")")) | D10: =IF($A10="","",발령대장_입력!$C7) | E10: =IF($A10="","",발령대장_입력!$A7&"에 임함"&IF(발령대장_입력!$B7="","",CHAR(10)&"("&발령대장_입력!$B7&")")&IF(발령대장_입력!$G7="","",CHAR(10)&"("&SUBSTITUTE(SUBSTITUTE(발령대장_입력!$G7,"호봉","")," ","")&")호봉을 급함")&CHAR(10)&"임용기간: "&YEAR(발령대장_입력!$E7)&"."&MONTH(발령대장_입력!$E7)&"."&DAY(발령대장_입력!$E7)&"."&" ~ "&YEAR(발령대장_입력!$F7)&"."&MONTH(발령대장_입력!$F7)&"."&DAY(발령대장_입력!$F7)&".") | F10: =IF($A10="","",IF(기본설정·안내!$B$5="","",기본설정·안내!$B$5)) | G10: =IF($A10="","",IF(기본설정·안내!$B$6="","",기본설정·안내!$B$6)) | H10: =IF($A10="","",IF(기본설정·안내!$B$7="","",기본설정·안내!$B$7)) | I10: =IF($A10="","",IF(기본설정·안내!$B$8="","",기본설정·안내!$B$8)) | J10: =IF($A10="","",IF(기본설정·안내!$B$9="","",기본설정·안내!$B$9))
A11: =IF(발령대장_입력!$C8="","",발령대장_입력!$E8) | B11: =IF($A11="","",IF(기본설정·안내!$B$4="","",기본설정·안내!$B$4)) | C11: =IF($A11="","",IF(발령대장_입력!$B8="",발령대장_입력!$A8,발령대장_입력!$A8&CHAR(10)&"("&발령대장_입력!$B8&")")) | D11: =IF($A11="","",발령대장_입력!$C8) | E11: =IF($A11="","",발령대장_입력!$A8&"에 임함"&IF(발령대장_입력!$B8="","",CHAR(10)&"("&발령대장_입력!$B8&")")&IF(발령대장_입력!$G8="","",CHAR(10)&"("&SUBSTITUTE(SUBSTITUTE(발령대장_입력!$G8,"호봉","")," ","")&")호봉을 급함")&CHAR(10)&"임용기간: "&YEAR(발령대장_입력!$E8)&"."&MONTH(발령대장_입력!$E8)&"."&DAY(발령대장_입력!$E8)&"."&" ~ "&YEAR(발령대장_입력!$F8)&"."&MONTH(발령대장_입력!$F8)&"."&DAY(발령대장_입력!$F8)&".") | F11: =IF($A11="","",IF(기본설정·안내!$B$5="","",기본설정·안내!$B$5)) | G11: =IF($A11="","",IF(기본설정·안내!$B$6="","",기본설정·안내!$B$6)) | H11: =IF($A11="","",IF(기본설정·안내!$B$7="","",기본설정·안내!$B$7)) | I11: =IF($A11="","",IF(기본설정·안내!$B$8="","",기본설정·안내!$B$8)) | J11: =IF($A11="","",IF(기본설정·안내!$B$9="","",기본설정·안내!$B$9))
A12: =IF(발령대장_입력!$C9="","",발령대장_입력!$E9) | B12: =IF($A12="","",IF(기본설정·안내!$B$4="","",기본설정·안내!$B$4)) | C12: =IF($A12="","",IF(발령대장_입력!$B9="",발령대장_입력!$A9,발령대장_입력!$A9&CHAR(10)&"("&발령대장_입력!$B9&")")) | D12: =IF($A12="","",발령대장_입력!$C9) | E12: =IF($A12="","",발령대장_입력!$A9&"에 임함"&IF(발령대장_입력!$B9="","",CHAR(10)&"("&발령대장_입력!$B9&")")&IF(발령대장_입력!$G9="","",CHAR(10)&"("&SUBSTITUTE(SUBSTITUTE(발령대장_입력!$G9,"호봉","")," ","")&")호봉을 급함")&CHAR(10)&"임용기간: "&YEAR(발령대장_입력!$E9)&"."&MONTH(발령대장_입력!$E9)&"."&DAY(발령대장_입력!$E9)&"."&" ~ "&YEAR(발령대장_입력!$F9)&"."&MONTH(발령대장_입력!$F9)&"."&DAY(발령대장_입력!$F9)&".") | F12: =IF($A12="","",IF(기본설정·안내!$B$5="","",기본설정·안내!$B$5)) | G12: =IF($A12="","",IF(기본설정·안내!$B$6="","",기본설정·안내!$B$6)) | H12: =IF($A12="","",IF(기본설정·안내!$B$7="","",기본설정·안내!$B$7)) | I12: =IF($A12="","",IF(기본설정·안내!$B$8="","",기본설정·안내!$B$8)) | J12: =IF($A12="","",IF(기본설정·안내!$B$9="","",기본설정·안내!$B$9))
A13: =IF(발령대장_입력!$C10="","",발령대장_입력!$E10) | B13: =IF($A13="","",IF(기본설정·안내!$B$4="","",기본설정·안내!$B$4)) | C13: =IF($A13="","",IF(발령대장_입력!$B10="",발령대장_입력!$A10,발령대장_입력!$A10&CHAR(10)&"("&발령대장_입력!$B10&")")) | D13: =IF($A13="","",발령대장_입력!$C10) | E13: =IF($A13="","",발령대장_입력!$A10&"에 임함"&IF(발령대장_입력!$B10="","",CHAR(10)&"("&발령대장_입력!$B10&")")&IF(발령대장_입력!$G10="","",CHAR(10)&"("&SUBSTITUTE(SUBSTITUTE(발령대장_입력!$G10,"호봉","")," ","")&")호봉을 급함")&CHAR(10)&"임용기간: "&YEAR(발령대장_입력!$E10)&"."&MONTH(발령대장_입력!$E10)&"."&DAY(발령대장_입력!$E10)&"."&" ~ "&YEAR(발령대장_입력!$F10)&"."&MONTH(발령대장_입력!$F10)&"."&DAY(발령대장_입력!$F10)&".") | F13: =IF($A13="","",IF(기본설정·안내!$B$5="","",기본설정·안내!$B$5)) | G13: =IF($A13="","",IF(기본설정·안내!$B$6="","",기본설정·안내!$B$6)) | H13: =IF($A13="","",IF(기본설정·안내!$B$7="","",기본설정·안내!$B$7)) | I13: =IF($A13="","",IF(기본설정·안내!$B$8="","",기본설정·안내!$B$8)) | J13: =IF($A13="","",IF(기본설정·안내!$B$9="","",기본설정·안내!$B$9))
A14: =IF(발령대장_입력!$C11="","",발령대장_입력!$E11) | B14: =IF($A14="","",IF(기본설정·안내!$B$4="","",기본설정·안내!$B$4)) | C14: =IF($A14="","",IF(발령대장_입력!$B11="",발령대장_입력!$A11,발령대장_입력!$A11&CHAR(10)&"("&발령대장_입력!$B11&")")) | D14: =IF($A14="","",발령대장_입력!$C11) | E14: =IF($A14="","",발령대장_입력!$A11&"에 임함"&IF(발령대장_입력!$B11="","",CHAR(10)&"("&발령대장_입력!$B11&")")&IF(발령대장_입력!$G11="","",CHAR(10)&"("&SUBSTITUTE(SUBSTITUTE(발령대장_입력!$G11,"호봉","")," ","")&")호봉을 급함")&CHAR(10)&"임용기간: "&YEAR(발령대장_입력!$E11)&"."&MONTH(발령대장_입력!$E11)&"."&DAY(발령대장_입력!$E11)&"."&" ~ "&YEAR(발령대장_입력!$F11)&"."&MONTH(발령대장_입력!$F11)&"."&DAY(발령대장_입력!$F11)&".") | F14: =IF($A14="","",IF(기본설정·안내!$B$5="","",기본설정·안내!$B$5)) | G14: =IF($A14="","",IF(기본설정·안내!$B$6="","",기본설정·안내!$B$6)) | H14: =IF($A14="","",IF(기본설정·안내!$B$7="","",기본설정·안내!$B$7)) | I14: =IF($A14="","",IF(기본설정·안내!$B$8="","",기본설정·안내!$B$8)) | J14: =IF($A14="","",IF(기본설정·안내!$B$9="","",기본설정·안내!$B$9))
A15: =IF(발령대장_입력!$C12="","",발령대장_입력!$E12) | B15: =IF($A15="","",IF(기본설정·안내!$B$4="","",기본설정·안내!$B$4)) | C15: =IF($A15="","",IF(발령대장_입력!$B12="",발령대장_입력!$A12,발령대장_입력!$A12&CHAR(10)&"("&발령대장_입력!$B12&")")) | D15: =IF($A15="","",발령대장_입력!$C12) | E15: =IF($A15="","",발령대장_입력!$A12&"에 임함"&IF(발령대장_입력!$B12="","",CHAR(10)&"("&발령대장_입력!$B12&")")&IF(발령대장_입력!$G12="","",CHAR(10)&"("&SUBSTITUTE(SUBSTITUTE(발령대장_입력!$G12,"호봉","")," ","")&")호봉을 급함")&CHAR(10)&"임용기간: "&YEAR(발령대장_입력!$E12)&"."&MONTH(발령대장_입력!$E12)&"."&DAY(발령대장_입력!$E12)&"."&" ~ "&YEAR(발령대장_입력!$F12)&"."&MONTH(발령대장_입력!$F12)&"."&DAY(발령대장_입력!$F12)&".") | F15: =IF($A15="","",IF(기본설정·안내!$B$5="","",기본설정·안내!$B$5)) | G15: =IF($A15="","",IF(기본설정·안내!$B$6="","",기본설정·안내!$B$6)) | H15: =IF($A15="","",IF(기본설정·안내!$B$7="","",기본설정·안내!$B$7)) | I15: =IF($A15="","",IF(기본설정·안내!$B$8="","",기본설정·안내!$B$8)) | J15: =IF($A15="","",IF(기본설정·안내!$B$9="","",기본설정·안내!$B$9))
A16: =IF(발령대장_입력!$C13="","",발령대장_입력!$E13) | B16: =IF($A16="","",IF(기본설정·안내!$B$4="","",기본설정·안내!$B$4)) | C16: =IF($A16="","",IF(발령대장_입력!$B13="",발령대장_입력!$A13,발령대장_입력!$A13&CHAR(10)&"("&발령대장_입력!$B13&")")) | D16: =IF($A16="","",발령대장_입력!$C13) | E16: =IF($A16="","",발령대장_입력!$A13&"에 임함"&IF(발령대장_입력!$B13="","",CHAR(10)&"("&발령대장_입력!$B13&")")&IF(발령대장_입력!$G13="","",CHAR(10)&"("&SUBSTITUTE(SUBSTITUTE(발령대장_입력!$G13,"호봉","")," ","")&")호봉을 급함")&CHAR(10)&"임용기간: "&YEAR(발령대장_입력!$E13)&"."&MONTH(발령대장_입력!$E13)&"."&DAY(발령대장_입력!$E13)&"."&" ~ "&YEAR(발령대장_입력!$F13)&"."&MONTH(발령대장_입력!$F13)&"."&DAY(발령대장_입력!$F13)&".") | F16: =IF($A16="","",IF(기본설정·안내!$B$5="","",기본설정·안내!$B$5)) | G16: =IF($A16="","",IF(기본설정·안내!$B$6="","",기본설정·안내!$B$6)) | H16: =IF($A16="","",IF(기본설정·안내!$B$7="","",기본설정·안내!$B$7)) | I16: =IF($A16="","",IF(기본설정·안내!$B$8="","",기본설정·안내!$B$8)) | J16: =IF($A16="","",IF(기본설정·안내!$B$9="","",기본설정·안내!$B$9))
... A20: =IF(발령대장_입력!$C17="","",발령대장_입력!$E17) | B20: =IF($A20="","",IF(기본설정·안내!$B$4="","",기본설정·안내!$B$4)) | C20: =IF($A20="","",IF(발령대장_입력!$B17="",발령대장_입력!$A17,발령대장_입력!$A17&CHAR(10)&"("&발령대장_입력!$B17&")")) | D20: =IF($A20="","",발령대장_입력!$C17) | E20: =IF($A20="","",발령대장_입력!$A17&"에 임함"&IF(발령대장_입력!$B17="","",CHAR(10)&"("&발령대장_입력!$B17&")")&IF(발령대장_입력!$G17="","",CHAR(10)&"("&SUBSTITUTE(SUBSTITUTE(발령대장_입력!$G17,"호봉","")," ","")&")호봉을 급함")&CHAR(10)&"임용기간: "&YEAR(발령대장_입력!$E17)&"."&MONTH(발령대장_입력!$E17)&"."&DAY(발령대장_입력!$E17)&"."&" ~ "&YEAR(발령대장_입력!$F17)&"."&MONTH(발령대장_입력!$F17)&"."&DAY(발령대장_입력!$F17)&".") | F20: =IF($A20="","",IF(기본설정·안내!$B$5="","",기본설정·안내!$B$5)) | G20: =IF($A20="","",IF(기본설정·안내!$B$6="","",기본설정·안내!$B$6)) | H20: =IF($A20="","",IF(기본설정·안내!$B$7="","",기본설정·안내!$B$7)) | I20: =IF($A20="","",IF(기본설정·안내!$B$8="","",기본설정·안내!$B$8)) | J20: =IF($A20="","",IF(기본설정·안내!$B$9="","",기본설정·안내!$B$9))
A21: =IF(발령대장_입력!#REF!="","",발령대장_입력!#REF!) -> #REF! | B21: =IF($A21="","",IF(기본설정·안내!$B$4="","",기본설정·안내!$B$4)) -> #REF! | C21: =IF($A21="","",IF(발령대장_입력!#REF!="",발령대장_입력!#REF!,발령대장_입력!#REF!&CHAR(10)&"("&발령대장_입력!#REF!&")")) -> #REF! | D21: =IF($A21="","",발령대장_입력!#REF!) -> #REF! | E21: =IF($A21="","",발령대장_입력!#REF!&"에 임함"&IF(발령대장_입력!#REF!="","",CHAR(10)&"("&발령대장_입력!#REF!&")")&IF(발령대장_입력!#REF!="","",CHAR(10)&"("&SUBSTITUTE(SUBSTITUTE(발령대장_입력!#REF!,"호봉","")," ","")&")호봉을 급함")&CHAR(10)&"임용기간: "&YEAR(발령대장_입력!#REF!)&"."&MONTH(발령대장_입력!#REF!)&"."&DAY(발령대장_입력!#REF!)&"."&" ~ "&YEAR(발령대장_입력!#REF!)&"."&MONTH(발령대장_입력!#REF!)&"."&DAY(발령대장_입력!#REF!)&".") -> #REF! | F21: =IF($A21="","",IF(기본설정·안내!$B$5="","",기본설정·안내!$B$5)) -> #REF! | G21: =IF($A21="","",IF(기본설정·안내!$B$6="","",기본설정·안내!$B$6)) -> #REF! | H21: =IF($A21="","",IF(기본설정·안내!$B$7="","",기본설정·안내!$B$7)) -> #REF! | I21: =IF($A21="","",IF(기본설정·안내!$B$8="","",기본설정·안내!$B$8)) -> #REF! | J21: =IF($A21="","",IF(기본설정·안내!$B$9="","",기본설정·안내!$B$9)) -> #REF!
A22: =IF(발령대장_입력!#REF!="","",발령대장_입력!#REF!) -> #REF! | B22: =IF($A22="","",IF(기본설정·안내!$B$4="","",기본설정·안내!$B$4)) -> #REF! | C22: =IF($A22="","",IF(발령대장_입력!#REF!="",발령대장_입력!#REF!,발령대장_입력!#REF!&CHAR(10)&"("&발령대장_입력!#REF!&")")) -> #REF! | D22: =IF($A22="","",발령대장_입력!#REF!) -> #REF! | E22: =IF($A22="","",발령대장_입력!#REF!&"에 임함"&IF(발령대장_입력!#REF!="","",CHAR(10)&"("&발령대장_입력!#REF!&")")&IF(발령대장_입력!#REF!="","",CHAR(10)&"("&SUBSTITUTE(SUBSTITUTE(발령대장_입력!#REF!,"호봉","")," ","")&")호봉을 급함")&CHAR(10)&"임용기간: "&YEAR(발령대장_입력!#REF!)&"."&MONTH(발령대장_입력!#REF!)&"."&DAY(발령대장_입력!#REF!)&"."&" ~ "&YEAR(발령대장_입력!#REF!)&"."&MONTH(발령대장_입력!#REF!)&"."&DAY(발령대장_입력!#REF!)&".") -> #REF! | F22: =IF($A22="","",IF(기본설정·안내!$B$5="","",기본설정·안내!$B$5)) -> #REF! | G22: =IF($A22="","",IF(기본설정·안내!$B$6="","",기본설정·안내!$B$6)) -> #REF! | H22: =IF($A22="","",IF(기본설정·안내!$B$7="","",기본설정·안내!$B$7)) -> #REF! | I22: =IF($A22="","",IF(기본설정·안내!$B$8="","",기본설정·안내!$B$8)) -> #REF! | J22: =IF($A22="","",IF(기본설정·안내!$B$9="","",기본설정·안내!$B$9)) -> #REF!
A23: =IF(발령대장_입력!#REF!="","",발령대장_입력!#REF!) -> #REF! | B23: =IF($A23="","",IF(기본설정·안내!$B$4="","",기본설정·안내!$B$4)) -> #REF! | C23: =IF($A23="","",IF(발령대장_입력!#REF!="",발령대장_입력!#REF!,발령대장_입력!#REF!&CHAR(10)&"("&발령대장_입력!#REF!&")")) -> #REF! | D23: =IF($A23="","",발령대장_입력!#REF!) -> #REF! | E23: =IF($A23="","",발령대장_입력!#REF!&"에 임함"&IF(발령대장_입력!#REF!="","",CHAR(10)&"("&발령대장_입력!#REF!&")")&IF(발령대장_입력!#REF!="","",CHAR(10)&"("&SUBSTITUTE(SUBSTITUTE(발령대장_입력!#REF!,"호봉","")," ","")&")호봉을 급함")&CHAR(10)&"임용기간: "&YEAR(발령대장_입력!#REF!)&"."&MONTH(발령대장_입력!#REF!)&"."&DAY(발령대장_입력!#REF!)&"."&" ~ "&YEAR(발령대장_입력!#REF!)&"."&MONTH(발령대장_입력!#REF!)&"."&DAY(발령대장_입력!#REF!)&".") -> #REF! | F23: =IF($A23="","",IF(기본설정·안내!$B$5="","",기본설정·안내!$B$5)) -> #REF! | G23: =IF($A23="","",IF(기본설정·안내!$B$6="","",기본설정·안내!$B$6)) -> #REF! | H23: =IF($A23="","",IF(기본설정·안내!$B$7="","",기본설정·안내!$B$7)) -> #REF! | I23: =IF($A23="","",IF(기본설정·안내!$B$8="","",기본설정·안내!$B$8)) -> #REF! | J23: =IF($A23="","",IF(기본설정·안내!$B$9="","",기본설정·안내!$B$9)) -> #REF!
A24: =IF(발령대장_입력!#REF!="","",발령대장_입력!#REF!) -> #REF! | B24: =IF($A24="","",IF(기본설정·안내!$B$4="","",기본설정·안내!$B$4)) -> #REF! | C24: =IF($A24="","",IF(발령대장_입력!#REF!="",발령대장_입력!#REF!,발령대장_입력!#REF!&CHAR(10)&"("&발령대장_입력!#REF!&")")) -> #REF! | D24: =IF($A24="","",발령대장_입력!#REF!) -> #REF! | E24: =IF($A24="","",발령대장_입력!#REF!&"에 임함"&IF(발령대장_입력!#REF!="","",CHAR(10)&"("&발령대장_입력!#REF!&")")&IF(발령대장_입력!#REF!="","",CHAR(10)&"("&SUBSTITUTE(SUBSTITUTE(발령대장_입력!#REF!,"호봉","")," ","")&")호봉을 급함")&CHAR(10)&"임용기간: "&YEAR(발령대장_입력!#REF!)&"."&MONTH(발령대장_입력!#REF!)&"."&DAY(발령대장_입력!#REF!)&"."&" ~ "&YEAR(발령대장_입력!#REF!)&"."&MONTH(발령대장_입력!#REF!)&"."&DAY(발령대장_입력!#REF!)&".") -> #REF! | F24: =IF($A24="","",IF(기본설정·안내!$B$5="","",기본설정·안내!$B$5)) -> #REF! | G24: =IF($A24="","",IF(기본설정·안내!$B$6="","",기본설정·안내!$B$6)) -> #REF! | H24: =IF($A24="","",IF(기본설정·안내!$B$7="","",기본설정·안내!$B$7)) -> #REF! | I24: =IF($A24="","",IF(기본설정·안내!$B$8="","",기본설정·안내!$B$8)) -> #REF! | J24: =IF($A24="","",IF(기본설정·안내!$B$9="","",기본설정·안내!$B$9)) -> #REF!
A25: =IF(발령대장_입력!#REF!="","",발령대장_입력!#REF!) -> #REF! | B25: =IF($A25="","",IF(기본설정·안내!$B$4="","",기본설정·안내!$B$4)) -> #REF! | C25: =IF($A25="","",IF(발령대장_입력!#REF!="",발령대장_입력!#REF!,발령대장_입력!#REF!&CHAR(10)&"("&발령대장_입력!#REF!&")")) -> #REF! | D25: =IF($A25="","",발령대장_입력!#REF!) -> #REF! | E25: =IF($A25="","",발령대장_입력!#REF!&"에 임함"&IF(발령대장_입력!#REF!="","",CHAR(10)&"("&발령대장_입력!#REF!&")")&IF(발령대장_입력!#REF!="","",CHAR(10)&"("&SUBSTITUTE(SUBSTITUTE(발령대장_입력!#REF!,"호봉","")," ","")&")호봉을 급함")&CHAR(10)&"임용기간: "&YEAR(발령대장_입력!#REF!)&"."&MONTH(발령대장_입력!#REF!)&"."&DAY(발령대장_입력!#REF!)&"."&" ~ "&YEAR(발령대장_입력!#REF!)&"."&MONTH(발령대장_입력!#REF!)&"."&DAY(발령대장_입력!#REF!)&".") -> #REF! | F25: =IF($A25="","",IF(기본설정·안내!$B$5="","",기본설정·안내!$B$5)) -> #REF! | G25: =IF($A25="","",IF(기본설정·안내!$B$6="","",기본설정·안내!$B$6)) -> #REF! | H25: =IF($A25="","",IF(기본설정·안내!$B$7="","",기본설정·안내!$B$7)) -> #REF! | I25: =IF($A25="","",IF(기본설정·안내!$B$8="","",기본설정·안내!$B$8)) -> #REF! | J25: =IF($A25="","",IF(기본설정·안내!$B$9="","",기본설정·안내!$B$9)) -> #REF!
A26: =IF(발령대장_입력!#REF!="","",발령대장_입력!#REF!) -> #REF! | B26: =IF($A26="","",IF(기본설정·안내!$B$4="","",기본설정·안내!$B$4)) -> #REF! | C26: =IF($A26="","",IF(발령대장_입력!#REF!="",발령대장_입력!#REF!,발령대장_입력!#REF!&CHAR(10)&"("&발령대장_입력!#REF!&")")) -> #REF! | D26: =IF($A26="","",발령대장_입력!#REF!) -> #REF! | E26: =IF($A26="","",발령대장_입력!#REF!&"에 임함"&IF(발령대장_입력!#REF!="","",CHAR(10)&"("&발령대장_입력!#REF!&")")&IF(발령대장_입력!#REF!="","",CHAR(10)&"("&SUBSTITUTE(SUBSTITUTE(발령대장_입력!#REF!,"호봉","")," ","")&")호봉을 급함")&CHAR(10)&"임용기간: "&YEAR(발령대장_입력!#REF!)&"."&MONTH(발령대장_입력!#REF!)&"."&DAY(발령대장_입력!#REF!)&"."&" ~ "&YEAR(발령대장_입력!#REF!)&"."&MONTH(발령대장_입력!#REF!)&"."&DAY(발령대장_입력!#REF!)&".") -> #REF! | F26: =IF($A26="","",IF(기본설정·안내!$B$5="","",기본설정·안내!$B$5)) -> #REF! | G26: =IF($A26="","",IF(기본설정·안내!$B$6="","",기본설정·안내!$B$6)) -> #REF! | H26: =IF($A26="","",IF(기본설정·안내!$B$7="","",기본설정·안내!$B$7)) -> #REF! | I26: =IF($A26="","",IF(기본설정·안내!$B$8="","",기본설정·안내!$B$8)) -> #REF! | J26: =IF($A26="","",IF(기본설정·안내!$B$9="","",기본설정·안내!$B$9)) -> #REF!
A27: =IF(발령대장_입력!#REF!="","",발령대장_입력!#REF!) -> #REF! | B27: =IF($A27="","",IF(기본설정·안내!$B$4="","",기본설정·안내!$B$4)) -> #REF! | C27: =IF($A27="","",IF(발령대장_입력!#REF!="",발령대장_입력!#REF!,발령대장_입력!#REF!&CHAR(10)&"("&발령대장_입력!#REF!&")")) -> #REF! | D27: =IF($A27="","",발령대장_입력!#REF!) -> #REF! | E27: =IF($A27="","",발령대장_입력!#REF!&"에 임함"&IF(발령대장_입력!#REF!="","",CHAR(10)&"("&발령대장_입력!#REF!&")")&IF(발령대장_입력!#REF!="","",CHAR(10)&"("&SUBSTITUTE(SUBSTITUTE(발령대장_입력!#REF!,"호봉","")," ","")&")호봉을 급함")&CHAR(10)&"임용기간: "&YEAR(발령대장_입력!#REF!)&"."&MONTH(발령대장_입력!#REF!)&"."&DAY(발령대장_입력!#REF!)&"."&" ~ "&YEAR(발령대장_입력!#REF!)&"."&MONTH(발령대장_입력!#REF!)&"."&DAY(발령대장_입력!#REF!)&".") -> #REF! | F27: =IF($A27="","",IF(기본설정·안내!$B$5="","",기본설정·안내!$B$5)) -> #REF! | G27: =IF($A27="","",IF(기본설정·안내!$B$6="","",기본설정·안내!$B$6)) -> #REF! | H27: =IF($A27="","",IF(기본설정·안내!$B$7="","",기본설정·안내!$B$7)) -> #REF! | I27: =IF($A27="","",IF(기본설정·안내!$B$8="","",기본설정·안내!$B$8)) -> #REF! | J27: =IF($A27="","",IF(기본설정·안내!$B$9="","",기본설정·안내!$B$9)) -> #REF!
A28: =IF(발령대장_입력!#REF!="","",발령대장_입력!#REF!) -> #REF! | B28: =IF($A28="","",IF(기본설정·안내!$B$4="","",기본설정·안내!$B$4)) -> #REF! | C28: =IF($A28="","",IF(발령대장_입력!#REF!="",발령대장_입력!#REF!,발령대장_입력!#REF!&CHAR(10)&"("&발령대장_입력!#REF!&")")) -> #REF! | D28: =IF($A28="","",발령대장_입력!#REF!) -> #REF! | E28: =IF($A28="","",발령대장_입력!#REF!&"에 임함"&IF(발령대장_입력!#REF!="","",CHAR(10)&"("&발령대장_입력!#REF!&")")&IF(발령대장_입력!#REF!="","",CHAR(10)&"("&SUBSTITUTE(SUBSTITUTE(발령대장_입력!#REF!,"호봉","")," ","")&")호봉을 급함")&CHAR(10)&"임용기간: "&YEAR(발령대장_입력!#REF!)&"."&MONTH(발령대장_입력!#REF!)&"."&DAY(발령대장_입력!#REF!)&"."&" ~ "&YEAR(발령대장_입력!#REF!)&"."&MONTH(발령대장_입력!#REF!)&"."&DAY(발령대장_입력!#REF!)&".") -> #REF! | F28: =IF($A28="","",IF(기본설정·안내!$B$5="","",기본설정·안내!$B$5)) -> #REF! | G28: =IF($A28="","",IF(기본설정·안내!$B$6="","",기본설정·안내!$B$6)) -> #REF! | H28: =IF($A28="","",IF(기본설정·안내!$B$7="","",기본설정·안내!$B$7)) -> #REF! | I28: =IF($A28="","",IF(기본설정·안내!$B$8="","",기본설정·안내!$B$8)) -> #REF! | J28: =IF($A28="","",IF(기본설정·안내!$B$9="","",기본설정·안내!$B$9)) -> #REF!
A29: =IF(발령대장_입력!#REF!="","",발령대장_입력!#REF!) -> #REF! | B29: =IF($A29="","",IF(기본설정·안내!$B$4="","",기본설정·안내!$B$4)) -> #REF! | C29: =IF($A29="","",IF(발령대장_입력!#REF!="",발령대장_입력!#REF!,발령대장_입력!#REF!&CHAR(10)&"("&발령대장_입력!#REF!&")")) -> #REF! | D29: =IF($A29="","",발령대장_입력!#REF!) -> #REF! | E29: =IF($A29="","",발령대장_입력!#REF!&"에 임함"&IF(발령대장_입력!#REF!="","",CHAR(10)&"("&발령대장_입력!#REF!&")")&IF(발령대장_입력!#REF!="","",CHAR(10)&"("&SUBSTITUTE(SUBSTITUTE(발령대장_입력!#REF!,"호봉","")," ","")&")호봉을 급함")&CHAR(10)&"임용기간: "&YEAR(발령대장_입력!#REF!)&"."&MONTH(발령대장_입력!#REF!)&"."&DAY(발령대장_입력!#REF!)&"."&" ~ "&YEAR(발령대장_입력!#REF!)&"."&MONTH(발령대장_입력!#REF!)&"."&DAY(발령대장_입력!#REF!)&".") -> #REF! | F29: =IF($A29="","",IF(기본설정·안내!$B$5="","",기본설정·안내!$B$5)) -> #REF! | G29: =IF($A29="","",IF(기본설정·안내!$B$6="","",기본설정·안내!$B$6)) -> #REF! | H29: =IF($A29="","",IF(기본설정·안내!$B$7="","",기본설정·안내!$B$7)) -> #REF! | I29: =IF($A29="","",IF(기본설정·안내!$B$8="","",기본설정·안내!$B$8)) -> #REF! | J29: =IF($A29="","",IF(기본설정·안내!$B$9="","",기본설정·안내!$B$9)) -> #REF!
A30: =IF(발령대장_입력!#REF!="","",발령대장_입력!#REF!) -> #REF! | B30: =IF($A30="","",IF(기본설정·안내!$B$4="","",기본설정·안내!$B$4)) -> #REF! | C30: =IF($A30="","",IF(발령대장_입력!#REF!="",발령대장_입력!#REF!,발령대장_입력!#REF!&CHAR(10)&"("&발령대장_입력!#REF!&")")) -> #REF! | D30: =IF($A30="","",발령대장_입력!#REF!) -> #REF! | E30: =IF($A30="","",발령대장_입력!#REF!&"에 임함"&IF(발령대장_입력!#REF!="","",CHAR(10)&"("&발령대장_입력!#REF!&")")&IF(발령대장_입력!#REF!="","",CHAR(10)&"("&SUBSTITUTE(SUBSTITUTE(발령대장_입력!#REF!,"호봉","")," ","")&")호봉을 급함")&CHAR(10)&"임용기간: "&YEAR(발령대장_입력!#REF!)&"."&MONTH(발령대장_입력!#REF!)&"."&DAY(발령대장_입력!#REF!)&"."&" ~ "&YEAR(발령대장_입력!#REF!)&"."&MONTH(발령대장_입력!#REF!)&"."&DAY(발령대장_입력!#REF!)&".") -> #REF! | F30: =IF($A30="","",IF(기본설정·안내!$B$5="","",기본설정·안내!$B$5)) -> #REF! | G30: =IF($A30="","",IF(기본설정·안내!$B$6="","",기본설정·안내!$B$6)) -> #REF! | H30: =IF($A30="","",IF(기본설정·안내!$B$7="","",기본설정·안내!$B$7)) -> #REF! | I30: =IF($A30="","",IF(기본설정·안내!$B$8="","",기본설정·안내!$B$8)) -> #REF! | J30: =IF($A30="","",IF(기본설정·안내!$B$9="","",기본설정·안내!$B$9)) -> #REF!
A31: =IF(발령대장_입력!#REF!="","",발령대장_입력!#REF!) -> #REF! | B31: =IF($A31="","",IF(기본설정·안내!$B$4="","",기본설정·안내!$B$4)) -> #REF! | C31: =IF($A31="","",IF(발령대장_입력!#REF!="",발령대장_입력!#REF!,발령대장_입력!#REF!&CHAR(10)&"("&발령대장_입력!#REF!&")")) -> #REF! | D31: =IF($A31="","",발령대장_입력!#REF!) -> #REF! | E31: =IF($A31="","",발령대장_입력!#REF!&"에 임함"&IF(발령대장_입력!#REF!="","",CHAR(10)&"("&발령대장_입력!#REF!&")")&IF(발령대장_입력!#REF!="","",CHAR(10)&"("&SUBSTITUTE(SUBSTITUTE(발령대장_입력!#REF!,"호봉","")," ","")&")호봉을 급함")&CHAR(10)&"임용기간: "&YEAR(발령대장_입력!#REF!)&"."&MONTH(발령대장_입력!#REF!)&"."&DAY(발령대장_입력!#REF!)&"."&" ~ "&YEAR(발령대장_입력!#REF!)&"."&MONTH(발령대장_입력!#REF!)&"."&DAY(발령대장_입력!#REF!)&".") -> #REF! | F31: =IF($A31="","",IF(기본설정·안내!$B$5="","",기본설정·안내!$B$5)) -> #REF! | G31: =IF($A31="","",IF(기본설정·안내!$B$6="","",기본설정·안내!$B$6)) -> #REF! | H31: =IF($A31="","",IF(기본설정·안내!$B$7="","",기본설정·안내!$B$7)) -> #REF! | I31: =IF($A31="","",IF(기본설정·안내!$B$8="","",기본설정·안내!$B$8)) -> #REF! | J31: =IF($A31="","",IF(기본설정·안내!$B$9="","",기본설정·안내!$B$9)) -> #REF!
A32: =IF(발령대장_입력!#REF!="","",발령대장_입력!#REF!) -> #REF! | B32: =IF($A32="","",IF(기본설정·안내!$B$4="","",기본설정·안내!$B$4)) -> #REF! | C32: =IF($A32="","",IF(발령대장_입력!#REF!="",발령대장_입력!#REF!,발령대장_입력!#REF!&CHAR(10)&"("&발령대장_입력!#REF!&")")) -> #REF! | D32: =IF($A32="","",발령대장_입력!#REF!) -> #REF! | E32: =IF($A32="","",발령대장_입력!#REF!&"에 임함"&IF(발령대장_입력!#REF!="","",CHAR(10)&"("&발령대장_입력!#REF!&")")&IF(발령대장_입력!#REF!="","",CHAR(10)&"("&SUBSTITUTE(SUBSTITUTE(발령대장_입력!#REF!,"호봉","")," ","")&")호봉을 급함")&CHAR(10)&"임용기간: "&YEAR(발령대장_입력!#REF!)&"."&MONTH(발령대장_입력!#REF!)&"."&DAY(발령대장_입력!#REF!)&"."&" ~ "&YEAR(발령대장_입력!#REF!)&"."&MONTH(발령대장_입력!#REF!)&"."&DAY(발령대장_입력!#REF!)&".") -> #REF! | F32: =IF($A32="","",IF(기본설정·안내!$B$5="","",기본설정·안내!$B$5)) -> #REF! | G32: =IF($A32="","",IF(기본설정·안내!$B$6="","",기본설정·안내!$B$6)) -> #REF! | H32: =IF($A32="","",IF(기본설정·안내!$B$7="","",기본설정·안내!$B$7)) -> #REF! | I32: =IF($A32="","",IF(기본설정·안내!$B$8="","",기본설정·안내!$B$8)) -> #REF! | J32: =IF($A32="","",IF(기본설정·안내!$B$9="","",기본설정·안내!$B$9)) -> #REF!
... A47: =IF(발령대장_입력!#REF!="","",발령대장_입력!#REF!) -> #REF! | B47: =IF($A47="","",IF(기본설정·안내!$B$4="","",기본설정·안내!$B$4)) -> #REF! | C47: =IF($A47="","",IF(발령대장_입력!#REF!="",발령대장_입력!#REF!,발령대장_입력!#REF!&CHAR(10)&"("&발령대장_입력!#REF!&")")) -> #REF! | D47: =IF($A47="","",발령대장_입력!#REF!) -> #REF! | E47: =IF($A47="","",발령대장_입력!#REF!&"에 임함"&IF(발령대장_입력!#REF!="","",CHAR(10)&"("&발령대장_입력!#REF!&")")&IF(발령대장_입력!#REF!="","",CHAR(10)&"("&SUBSTITUTE(SUBSTITUTE(발령대장_입력!#REF!,"호봉","")," ","")&")호봉을 급함")&CHAR(10)&"임용기간: "&YEAR(발령대장_입력!#REF!)&"."&MONTH(발령대장_입력!#REF!)&"."&DAY(발령대장_입력!#REF!)&"."&" ~ "&YEAR(발령대장_입력!#REF!)&"."&MONTH(발령대장_입력!#REF!)&"."&DAY(발령대장_입력!#REF!)&".") -> #REF! | F47: =IF($A47="","",IF(기본설정·안내!$B$5="","",기본설정·안내!$B$5)) -> #REF! | G47: =IF($A47="","",IF(기본설정·안내!$B$6="","",기본설정·안내!$B$6)) -> #REF! | H47: =IF($A47="","",IF(기본설정·안내!$B$7="","",기본설정·안내!$B$7)) -> #REF! | I47: =IF($A47="","",IF(기본설정·안내!$B$8="","",기본설정·안내!$B$8)) -> #REF! | J47: =IF($A47="","",IF(기본설정·안내!$B$9="","",기본설정·안내!$B$9)) -> #REF!
A48: =IF(발령대장_입력!$C45="","",발령대장_입력!$E45) | B48: =IF($A48="","",IF(기본설정·안내!$B$4="","",기본설정·안내!$B$4)) | C48: =IF($A48="","",IF(발령대장_입력!$B45="",발령대장_입력!$A45,발령대장_입력!$A45&CHAR(10)&"("&발령대장_입력!$B45&")")) | D48: =IF($A48="","",발령대장_입력!$C45) | E48: =IF($A48="","",발령대장_입력!$A45&"에 임함"&IF(발령대장_입력!$B45="","",CHAR(10)&"("&발령대장_입력!$B45&")")&IF(발령대장_입력!$G45="","",CHAR(10)&"("&SUBSTITUTE(SUBSTITUTE(발령대장_입력!$G45,"호봉","")," ","")&")호봉을 급함")&CHAR(10)&"임용기간: "&YEAR(발령대장_입력!$E45)&"."&MONTH(발령대장_입력!$E45)&"."&DAY(발령대장_입력!$E45)&"."&" ~ "&YEAR(발령대장_입력!$F45)&"."&MONTH(발령대장_입력!$F45)&"."&DAY(발령대장_입력!$F45)&".") | F48: =IF($A48="","",IF(기본설정·안내!$B$5="","",기본설정·안내!$B$5)) | G48: =IF($A48="","",IF(기본설정·안내!$B$6="","",기본설정·안내!$B$6)) | H48: =IF($A48="","",IF(기본설정·안내!$B$7="","",기본설정·안내!$B$7)) | I48: =IF($A48="","",IF(기본설정·안내!$B$8="","",기본설정·안내!$B$8)) | J48: =IF($A48="","",IF(기본설정·안내!$B$9="","",기본설정·안내!$B$9))
A49: =IF(발령대장_입력!$C46="","",발령대장_입력!$E46) | B49: =IF($A49="","",IF(기본설정·안내!$B$4="","",기본설정·안내!$B$4)) | C49: =IF($A49="","",IF(발령대장_입력!$B46="",발령대장_입력!$A46,발령대장_입력!$A46&CHAR(10)&"("&발령대장_입력!$B46&")")) | D49: =IF($A49="","",발령대장_입력!$C46) | E49: =IF($A49="","",발령대장_입력!$A46&"에 임함"&IF(발령대장_입력!$B46="","",CHAR(10)&"("&발령대장_입력!$B46&")")&IF(발령대장_입력!$G46="","",CHAR(10)&"("&SUBSTITUTE(SUBSTITUTE(발령대장_입력!$G46,"호봉","")," ","")&")호봉을 급함")&CHAR(10)&"임용기간: "&YEAR(발령대장_입력!$E46)&"."&MONTH(발령대장_입력!$E46)&"."&DAY(발령대장_입력!$E46)&"."&" ~ "&YEAR(발령대장_입력!$F46)&"."&MONTH(발령대장_입력!$F46)&"."&DAY(발령대장_입력!$F46)&".") | F49: =IF($A49="","",IF(기본설정·안내!$B$5="","",기본설정·안내!$B$5)) | G49: =IF($A49="","",IF(기본설정·안내!$B$6="","",기본설정·안내!$B$6)) | H49: =IF($A49="","",IF(기본설정·안내!$B$7="","",기본설정·안내!$B$7)) | I49: =IF($A49="","",IF(기본설정·안내!$B$8="","",기본설정·안내!$B$8)) | J49: =IF($A49="","",IF(기본설정·안내!$B$9="","",기본설정·안내!$B$9))
A50: =IF(발령대장_입력!$C47="","",발령대장_입력!$E47) | B50: =IF($A50="","",IF(기본설정·안내!$B$4="","",기본설정·안내!$B$4)) | C50: =IF($A50="","",IF(발령대장_입력!$B47="",발령대장_입력!$A47,발령대장_입력!$A47&CHAR(10)&"("&발령대장_입력!$B47&")")) | D50: =IF($A50="","",발령대장_입력!$C47) | E50: =IF($A50="","",발령대장_입력!$A47&"에 임함"&IF(발령대장_입력!$B47="","",CHAR(10)&"("&발령대장_입력!$B47&")")&IF(발령대장_입력!$G47="","",CHAR(10)&"("&SUBSTITUTE(SUBSTITUTE(발령대장_입력!$G47,"호봉","")," ","")&")호봉을 급함")&CHAR(10)&"임용기간: "&YEAR(발령대장_입력!$E47)&"."&MONTH(발령대장_입력!$E47)&"."&DAY(발령대장_입력!$E47)&"."&" ~ "&YEAR(발령대장_입력!$F47)&"."&MONTH(발령대장_입력!$F47)&"."&DAY(발령대장_입력!$F47)&".") | F50: =IF($A50="","",IF(기본설정·안내!$B$5="","",기본설정·안내!$B$5)) | G50: =IF($A50="","",IF(기본설정·안내!$B$6="","",기본설정·안내!$B$6)) | H50: =IF($A50="","",IF(기본설정·안내!$B$7="","",기본설정·안내!$B$7)) | I50: =IF($A50="","",IF(기본설정·안내!$B$8="","",기본설정·안내!$B$8)) | J50: =IF($A50="","",IF(기본설정·안내!$B$9="","",기본설정·안내!$B$9))
A51: =IF(발령대장_입력!$C48="","",발령대장_입력!$E48) | B51: =IF($A51="","",IF(기본설정·안내!$B$4="","",기본설정·안내!$B$4)) | C51: =IF($A51="","",IF(발령대장_입력!$B48="",발령대장_입력!$A48,발령대장_입력!$A48&CHAR(10)&"("&발령대장_입력!$B48&")")) | D51: =IF($A51="","",발령대장_입력!$C48) | E51: =IF($A51="","",발령대장_입력!$A48&"에 임함"&IF(발령대장_입력!$B48="","",CHAR(10)&"("&발령대장_입력!$B48&")")&IF(발령대장_입력!$G48="","",CHAR(10)&"("&SUBSTITUTE(SUBSTITUTE(발령대장_입력!$G48,"호봉","")," ","")&")호봉을 급함")&CHAR(10)&"임용기간: "&YEAR(발령대장_입력!$E48)&"."&MONTH(발령대장_입력!$E48)&"."&DAY(발령대장_입력!$E48)&"."&" ~ "&YEAR(발령대장_입력!$F48)&"."&MONTH(발령대장_입력!$F48)&"."&DAY(발령대장_입력!$F48)&".") | F51: =IF($A51="","",IF(기본설정·안내!$B$5="","",기본설정·안내!$B$5)) | G51: =IF($A51="","",IF(기본설정·안내!$B$6="","",기본설정·안내!$B$6)) | H51: =IF($A51="","",IF(기본설정·안내!$B$7="","",기본설정·안내!$B$7)) | I51: =IF($A51="","",IF(기본설정·안내!$B$8="","",기본설정·안내!$B$8)) | J51: =IF($A51="","",IF(기본설정·안내!$B$9="","",기본설정·안내!$B$9))
A52: =IF(발령대장_입력!$C49="","",발령대장_입력!$E49) | B52: =IF($A52="","",IF(기본설정·안내!$B$4="","",기본설정·안내!$B$4)) | C52: =IF($A52="","",IF(발령대장_입력!$B49="",발령대장_입력!$A49,발령대장_입력!$A49&CHAR(10)&"("&발령대장_입력!$B49&")")) | D52: =IF($A52="","",발령대장_입력!$C49) | E52: =IF($A52="","",발령대장_입력!$A49&"에 임함"&IF(발령대장_입력!$B49="","",CHAR(10)&"("&발령대장_입력!$B49&")")&IF(발령대장_입력!$G49="","",CHAR(10)&"("&SUBSTITUTE(SUBSTITUTE(발령대장_입력!$G49,"호봉","")," ","")&")호봉을 급함")&CHAR(10)&"임용기간: "&YEAR(발령대장_입력!$E49)&"."&MONTH(발령대장_입력!$E49)&"."&DAY(발령대장_입력!$E49)&"."&" ~ "&YEAR(발령대장_입력!$F49)&"."&MONTH(발령대장_입력!$F49)&"."&DAY(발령대장_입력!$F49)&".") | F52: =IF($A52="","",IF(기본설정·안내!$B$5="","",기본설정·안내!$B$5)) | G52: =IF($A52="","",IF(기본설정·안내!$B$6="","",기본설정·안내!$B$6)) | H52: =IF($A52="","",IF(기본설정·안내!$B$7="","",기본설정·안내!$B$7)) | I52: =IF($A52="","",IF(기본설정·안내!$B$8="","",기본설정·안내!$B$8)) | J52: =IF($A52="","",IF(기본설정·안내!$B$9="","",기본설정·안내!$B$9))
A53: =IF(발령대장_입력!$C50="","",발령대장_입력!$E50) | B53: =IF($A53="","",IF(기본설정·안내!$B$4="","",기본설정·안내!$B$4)) | C53: =IF($A53="","",IF(발령대장_입력!$B50="",발령대장_입력!$A50,발령대장_입력!$A50&CHAR(10)&"("&발령대장_입력!$B50&")")) | D53: =IF($A53="","",발령대장_입력!$C50) | E53: =IF($A53="","",발령대장_입력!$A50&"에 임함"&IF(발령대장_입력!$B50="","",CHAR(10)&"("&발령대장_입력!$B50&")")&IF(발령대장_입력!$G50="","",CHAR(10)&"("&SUBSTITUTE(SUBSTITUTE(발령대장_입력!$G50,"호봉","")," ","")&")호봉을 급함")&CHAR(10)&"임용기간: "&YEAR(발령대장_입력!$E50)&"."&MONTH(발령대장_입력!$E50)&"."&DAY(발령대장_입력!$E50)&"."&" ~ "&YEAR(발령대장_입력!$F50)&"."&MONTH(발령대장_입력!$F50)&"."&DAY(발령대장_입력!$F50)&".") | F53: =IF($A53="","",IF(기본설정·안내!$B$5="","",기본설정·안내!$B$5)) | G53: =IF($A53="","",IF(기본설정·안내!$B$6="","",기본설정·안내!$B$6)) | H53: =IF($A53="","",IF(기본설정·안내!$B$7="","",기본설정·안내!$B$7)) | I53: =IF($A53="","",IF(기본설정·안내!$B$8="","",기본설정·안내!$B$8)) | J53: =IF($A53="","",IF(기본설정·안내!$B$9="","",기본설정·안내!$B$9))
A54: =IF(발령대장_입력!$C51="","",발령대장_입력!$E51) | B54: =IF($A54="","",IF(기본설정·안내!$B$4="","",기본설정·안내!$B$4)) | C54: =IF($A54="","",IF(발령대장_입력!$B51="",발령대장_입력!$A51,발령대장_입력!$A51&CHAR(10)&"("&발령대장_입력!$B51&")")) | D54: =IF($A54="","",발령대장_입력!$C51) | E54: =IF($A54="","",발령대장_입력!$A51&"에 임함"&IF(발령대장_입력!$B51="","",CHAR(10)&"("&발령대장_입력!$B51&")")&IF(발령대장_입력!$G51="","",CHAR(10)&"("&SUBSTITUTE(SUBSTITUTE(발령대장_입력!$G51,"호봉","")," ","")&")호봉을 급함")&CHAR(10)&"임용기간: "&YEAR(발령대장_입력!$E51)&"."&MONTH(발령대장_입력!$E51)&"."&DAY(발령대장_입력!$E51)&"."&" ~ "&YEAR(발령대장_입력!$F51)&"."&MONTH(발령대장_입력!$F51)&"."&DAY(발령대장_입력!$F51)&".") | F54: =IF($A54="","",IF(기본설정·안내!$B$5="","",기본설정·안내!$B$5)) | G54: =IF($A54="","",IF(기본설정·안내!$B$6="","",기본설정·안내!$B$6)) | H54: =IF($A54="","",IF(기본설정·안내!$B$7="","",기본설정·안내!$B$7)) | I54: =IF($A54="","",IF(기본설정·안내!$B$8="","",기본설정·안내!$B$8)) | J54: =IF($A54="","",IF(기본설정·안내!$B$9="","",기본설정·안내!$B$9))
A55: =IF(발령대장_입력!$C52="","",발령대장_입력!$E52) | B55: =IF($A55="","",IF(기본설정·안내!$B$4="","",기본설정·안내!$B$4)) | C55: =IF($A55="","",IF(발령대장_입력!$B52="",발령대장_입력!$A52,발령대장_입력!$A52&CHAR(10)&"("&발령대장_입력!$B52&")")) | D55: =IF($A55="","",발령대장_입력!$C52) | E55: =IF($A55="","",발령대장_입력!$A52&"에 임함"&IF(발령대장_입력!$B52="","",CHAR(10)&"("&발령대장_입력!$B52&")")&IF(발령대장_입력!$G52="","",CHAR(10)&"("&SUBSTITUTE(SUBSTITUTE(발령대장_입력!$G52,"호봉","")," ","")&")호봉을 급함")&CHAR(10)&"임용기간: "&YEAR(발령대장_입력!$E52)&"."&MONTH(발령대장_입력!$E52)&"."&DAY(발령대장_입력!$E52)&"."&" ~ "&YEAR(발령대장_입력!$F52)&"."&MONTH(발령대장_입력!$F52)&"."&DAY(발령대장_입력!$F52)&".") | F55: =IF($A55="","",IF(기본설정·안내!$B$5="","",기본설정·안내!$B$5)) | G55: =IF($A55="","",IF(기본설정·안내!$B$6="","",기본설정·안내!$B$6)) | H55: =IF($A55="","",IF(기본설정·안내!$B$7="","",기본설정·안내!$B$7)) | I55: =IF($A55="","",IF(기본설정·안내!$B$8="","",기본설정·안내!$B$8)) | J55: =IF($A55="","",IF(기본설정·안내!$B$9="","",기본설정·안내!$B$9))
A56: =IF(발령대장_입력!$C53="","",발령대장_입력!$E53) | B56: =IF($A56="","",IF(기본설정·안내!$B$4="","",기본설정·안내!$B$4)) | C56: =IF($A56="","",IF(발령대장_입력!$B53="",발령대장_입력!$A53,발령대장_입력!$A53&CHAR(10)&"("&발령대장_입력!$B53&")")) | D56: =IF($A56="","",발령대장_입력!$C53) | E56: =IF($A56="","",발령대장_입력!$A53&"에 임함"&IF(발령대장_입력!$B53="","",CHAR(10)&"("&발령대장_입력!$B53&")")&IF(발령대장_입력!$G53="","",CHAR(10)&"("&SUBSTITUTE(SUBSTITUTE(발령대장_입력!$G53,"호봉","")," ","")&")호봉을 급함")&CHAR(10)&"임용기간: "&YEAR(발령대장_입력!$E53)&"."&MONTH(발령대장_입력!$E53)&"."&DAY(발령대장_입력!$E53)&"."&" ~ "&YEAR(발령대장_입력!$F53)&"."&MONTH(발령대장_입력!$F53)&"."&DAY(발령대장_입력!$F53)&".") | F56: =IF($A56="","",IF(기본설정·안내!$B$5="","",기본설정·안내!$B$5)) | G56: =IF($A56="","",IF(기본설정·안내!$B$6="","",기본설정·안내!$B$6)) | H56: =IF($A56="","",IF(기본설정·안내!$B$7="","",기본설정·안내!$B$7)) | I56: =IF($A56="","",IF(기본설정·안내!$B$8="","",기본설정·안내!$B$8)) | J56: =IF($A56="","",IF(기본설정·안내!$B$9="","",기본설정·안내!$B$9))
A57: =IF(발령대장_입력!$C54="","",발령대장_입력!$E54) | B57: =IF($A57="","",IF(기본설정·안내!$B$4="","",기본설정·안내!$B$4)) | C57: =IF($A57="","",IF(발령대장_입력!$B54="",발령대장_입력!$A54,발령대장_입력!$A54&CHAR(10)&"("&발령대장_입력!$B54&")")) | D57: =IF($A57="","",발령대장_입력!$C54) | E57: =IF($A57="","",발령대장_입력!$A54&"에 임함"&IF(발령대장_입력!$B54="","",CHAR(10)&"("&발령대장_입력!$B54&")")&IF(발령대장_입력!$G54="","",CHAR(10)&"("&SUBSTITUTE(SUBSTITUTE(발령대장_입력!$G54,"호봉","")," ","")&")호봉을 급함")&CHAR(10)&"임용기간: "&YEAR(발령대장_입력!$E54)&"."&MONTH(발령대장_입력!$E54)&"."&DAY(발령대장_입력!$E54)&"."&" ~ "&YEAR(발령대장_입력!$F54)&"."&MONTH(발령대장_입력!$F54)&"."&DAY(발령대장_입력!$F54)&".") | F57: =IF($A57="","",IF(기본설정·안내!$B$5="","",기본설정·안내!$B$5)) | G57: =IF($A57="","",IF(기본설정·안내!$B$6="","",기본설정·안내!$B$6)) | H57: =IF($A57="","",IF(기본설정·안내!$B$7="","",기본설정·안내!$B$7)) | I57: =IF($A57="","",IF(기본설정·안내!$B$8="","",기본설정·안내!$B$8)) | J57: =IF($A57="","",IF(기본설정·안내!$B$9="","",기본설정·안내!$B$9))
A58: =IF(발령대장_입력!$C55="","",발령대장_입력!$E55) | B58: =IF($A58="","",IF(기본설정·안내!$B$4="","",기본설정·안내!$B$4)) | C58: =IF($A58="","",IF(발령대장_입력!$B55="",발령대장_입력!$A55,발령대장_입력!$A55&CHAR(10)&"("&발령대장_입력!$B55&")")) | D58: =IF($A58="","",발령대장_입력!$C55) | E58: =IF($A58="","",발령대장_입력!$A55&"에 임함"&IF(발령대장_입력!$B55="","",CHAR(10)&"("&발령대장_입력!$B55&")")&IF(발령대장_입력!$G55="","",CHAR(10)&"("&SUBSTITUTE(SUBSTITUTE(발령대장_입력!$G55,"호봉","")," ","")&")호봉을 급함")&CHAR(10)&"임용기간: "&YEAR(발령대장_입력!$E55)&"."&MONTH(발령대장_입력!$E55)&"."&DAY(발령대장_입력!$E55)&"."&" ~ "&YEAR(발령대장_입력!$F55)&"."&MONTH(발령대장_입력!$F55)&"."&DAY(발령대장_입력!$F55)&".") | F58: =IF($A58="","",IF(기본설정·안내!$B$5="","",기본설정·안내!$B$5)) | G58: =IF($A58="","",IF(기본설정·안내!$B$6="","",기본설정·안내!$B$6)) | H58: =IF($A58="","",IF(기본설정·안내!$B$7="","",기본설정·안내!$B$7)) | I58: =IF($A58="","",IF(기본설정·안내!$B$8="","",기본설정·안내!$B$8)) | J58: =IF($A58="","",IF(기본설정·안내!$B$9="","",기본설정·안내!$B$9))
...
